<?xml version="1.0"?>
<!-- =================================================================================== -->
<!-- |    This document was autogenerated by xacro from motiv_xlink_moveit_studio.hw.xacro | -->
<!-- |    EDITING THIS FILE BY HAND IS NOT RECOMMENDED                                 | -->
<!-- =================================================================================== -->
<robot name="xlink">
  <!-- Create servicer sled -->
  <link name="servicer_sled_link">
    <visual>
      <geometry>
        <mesh filename="file://$(find atomos_xlink_hw_config)/description/assets/craft.stl"
          scale="0.1 0.1 0.1" />
       </geometry>
    </visual>
    <collision>
      <geometry>
        <mesh filename="file://$(find atomos_xlink_hw_config)/description/assets/craft.stl"
          scale="0.1 0.1 0.1" />
      </geometry>
    </collision>
  </link>
  <joint name="servicer_sled_joint" type="fixed">
    <parent link="world" />
    <child link="servicer_sled_link" />
    <origin xyz="0 0 0" rpy="0 0 0" />
  </joint>
  <!-- Create world link -->
  <link name="world"/>
  <!-- LINKS -->
  <link name="base_link">
    <inertial>
      <origin rpy="0 0 0" xyz="-0.0007 -0.0009 0.0442"/>
      <mass value="0.7557"/>
      <inertia ixx=".0031" ixy="0" ixz="0" iyy=".0031" iyz="0" izz="0.0031"/>
    </inertial>
    <visual>
      <origin rpy="0 0 0" xyz="0 0 0"/>
      <geometry>
        <mesh filename="package://xlink_description/meshes/visual/base_link.dae" />
      </geometry>
    </visual>
    <collision>
      <origin rpy="0 0 0" xyz="0 0 0"/>
      <geometry>
        <mesh filename="package://xlink_description/meshes/collision/base_link.stl" />
      </geometry>
    </collision>
  </link>
  <link name="link_1">
    <inertial>
      <origin rpy="0 0 0" xyz="0 -.0301 -.1064"/>
      <mass value="4.9525"/>
      <inertia ixx=".2942" ixy="0" ixz="0" iyy=".3976" iyz="-.0147" izz=".3491"/>
    </inertial>
    <visual>
      <origin rpy="0 0 0" xyz="0 0 0"/>
      <geometry>
        <mesh filename="package://xlink_description/meshes/visual/link_1.dae" />
      </geometry>
    </visual>
    <collision>
      <origin rpy="0 0 0" xyz="0 0 0"/>
      <geometry>
        <mesh filename="package://xlink_description/meshes/collision/link_1.stl"/>
      </geometry>
    </collision>
  </link>
  <link name="link_2">
    <inertial>
      <origin rpy="0 0 0" xyz="0 .0296 -.0197"/>
      <mass value=".5943"/>
      <inertia ixx=".0012" ixy="0" ixz="0" iyy=".0014" iyz=".0002" izz=".0016"/>
    </inertial>
    <visual>
      <origin rpy="0 0 0" xyz="0 0 0"/>
      <geometry>
        <mesh filename="package://xlink_description/meshes/visual/link_2.dae"/>
      </geometry>
    </visual>
    <collision>
      <origin rpy="0 0 0" xyz="0 0 0"/>
      <geometry>
        <mesh filename="package://xlink_description/meshes/collision/link_2.stl"/>
      </geometry>
    </collision>
  </link>
  <link name="link_3">
    <inertial>
      <origin rpy="0 0 0" xyz="0 .0288 -.1022"/>
      <mass value="4.7009"/>
      <inertia ixx=".0593" ixy="0" ixz="0" iyy=".0544" iyz=".0129" izz=".0117"/>
    </inertial>
    <visual>
      <origin rpy="0 0 0" xyz="0 0 0"/>
      <geometry>
        <mesh filename="package://xlink_description/meshes/visual/link_3.dae"/>
      </geometry>
    </visual>
    <collision>
      <origin rpy="0 0 0" xyz="0 0 0"/>
      <geometry>
        <mesh filename="package://xlink_description/meshes/collision/link_3.stl"/>
      </geometry>
    </collision>
  </link>
  <link name="link_4">
    <inertial>
      <origin rpy="0 0 0" xyz="0 -.0271 -.0184"/>
      <mass value=".5703"/>
      <inertia ixx=".0010" ixy="0" ixz="0" iyy=".0013" iyz="-.0002" izz=".0014"/>
    </inertial>
    <visual>
      <origin rpy="0 0 0" xyz="0 0 0"/>
      <geometry>
        <mesh filename="package://xlink_description/meshes/visual/link_4.dae"/>
      </geometry>
    </visual>
    <collision>
      <origin rpy="0 0 0" xyz="0 0 0"/>
      <geometry>
        <mesh filename="package://xlink_description/meshes/collision/link_4.stl"/>
      </geometry>
    </collision>
  </link>
  <link name="link_5">
    <inertial>
      <origin rpy="0 0 0" xyz="0 -.0288 -.1022"/>
      <mass value="4.7009"/>
      <inertia ixx=".0593" ixy="0" ixz="0" iyy=".0544" iyz="-.0129" izz=".0117"/>
    </inertial>
    <visual>
      <origin rpy="0 0 0" xyz="0 0 0"/>
      <geometry>
        <mesh filename="package://xlink_description/meshes/visual/link_5.dae"/>
      </geometry>
    </visual>
    <collision>
      <origin rpy="0 0 0" xyz="0 0 0"/>
      <geometry>
        <mesh filename="package://xlink_description/meshes/collision/link_5.stl"/>
      </geometry>
    </collision>
  </link>
  <link name="link_6">
    <inertial>
      <origin rpy="0 0 0" xyz="0 .0271 -.0184"/>
      <mass value=".5703"/>
      <inertia ixx=".0010" ixy="0" ixz="0" iyy="0.0013" iyz=".0002" izz=".0014"/>
    </inertial>
    <visual>
      <origin rpy="0 0 0" xyz="0 0 0"/>
      <geometry>
        <mesh filename="package://xlink_description/meshes/visual/link_6.dae"/>
      </geometry>
    </visual>
    <collision>
      <origin rpy="0 0 0" xyz="0 0 0"/>
      <geometry>
        <mesh filename="package://xlink_description/meshes/collision/link_6.stl"/>
      </geometry>
    </collision>
  </link>
  <link name="link_7">
    <inertial>
      <origin rpy="0 0 0" xyz="-.0015 0 .1630"/>
      <mass value="3.2507"/>
      <inertia ixx=".2791" ixy=".0197" ixz=".0007" iyy=".2804" iyz=".0011" izz=".5222"/>
    </inertial>
    <visual>
      <origin rpy="0 0 0" xyz="0 0 0"/>
      <geometry>
        <mesh filename="package://xlink_description/meshes/visual/link_7.dae"/>
      </geometry>
    </visual>
    <collision>
      <origin rpy="0 0 0" xyz="0 0 0"/>
      <geometry>
        <mesh filename="package://xlink_description/meshes/collision/link_7.stl"/>
      </geometry>
    </collision>
  </link>
  <!-- JOINTS -->
  <!-- Dynamics and velocity limits are placeholders -->
  <joint name="base_joint" type="fixed">
    <origin rpy="-3.14159 -1.5707963267948966 0.0" xyz="0 0 0" />
    <parent link="world"/>
    <child link="base_link"/>
  </joint>
  <joint name="joint_1" type="revolute">
    <origin rpy="0 0 0" xyz="0 0 0.387"/>
    <parent link="base_link"/>
    <child link="link_1"/>
    <axis xyz="0 0 1"/>
    <limit effort="250" lower="-2.8798" upper="2.8798" velocity="0.2"/>
    <dynamics damping="20.0" friction="4.0"/>
  </joint>
  <joint name="joint_2" type="revolute">
    <origin rpy="1.5708 0 0" xyz="0 -.159 0"/>
    <parent link="link_1"/>
    <child link="link_2"/>
    <axis xyz="0 0 1"/>
    <limit effort="250" lower="-2.8798" upper="2.8798" velocity="0.2"/>
    <dynamics damping="20.0" friction="4.0"/>
  </joint>
  <joint name="joint_3" type="revolute">
    <origin rpy="-1.5708 0 0" xyz="0 .328 0"/>
    <parent link="link_2"/>
    <child link="link_3"/>
    <axis xyz="0 0 1"/>
    <limit effort="120" lower="-3.2289" upper="2.5307" velocity="0.3"/>
    <dynamics damping="20.0" friction="4.0"/>
  </joint>
  <joint name="joint_4" type="revolute">
    <origin rpy="-1.5708 0 0" xyz="0 .155 0"/>
    <parent link="link_3"/>
    <child link="link_4"/>
    <axis xyz="0 0 1"/>
    <limit effort="120" lower="-2.8798" upper="2.8798" velocity="0.3"/>
    <dynamics damping="20.0" friction="4.0"/>
  </joint>
  <joint name="joint_5" type="revolute">
    <origin rpy="1.5708 0 0" xyz="0 -.325 0"/>
    <parent link="link_4"/>
    <child link="link_5"/>
    <axis xyz="0 0 1"/>
    <limit effort="120" lower="-3.927" upper="1.8326" velocity="0.3"/>
    <dynamics damping="20.0" friction="4.0"/>
  </joint>
  <joint name="joint_6" type="revolute">
    <origin rpy="1.5708 0 0" xyz="0 -.155 0"/>
    <parent link="link_5"/>
    <child link="link_6"/>
    <axis xyz="0 0 1"/>
    <limit effort="120" lower="-3.2289" upper="2.5307" velocity="0.3"/>
    <dynamics damping="20.0" friction="4.0"/>
  </joint>
  <joint name="joint_7" type="revolute">
    <origin rpy="-1.5708 0 0" xyz="0 0 0"/>
    <parent link="link_6"/>
    <child link="link_7"/>
    <axis xyz="0 0 1"/>
    <limit effort="120" lower="-1.8326" upper="3.927" velocity="0.3"/>
    <dynamics damping="20.0" friction="4.0"/>
  </joint>
  <!--Force/Torque Sensor Link-->
  <link name="fts_link">
    <inertial>
      <origin rpy="0 0 0" xyz="0 0 0"/>
      <mass value="0.01"/>
      <inertia ixx="1e-6" ixy="0" ixz="0" iyy="1e-6" iyz="0" izz="1e-6"/>
    </inertial>
  </link>
  <!--Force/Torque Sensor Joint-->
  <joint name="fts_joint" type="fixed">
    <origin rpy="3.1416 0 3.1416" xyz="0 0 0.26643"/>
    <parent link="link_7"/>
    <child link="fts_link"/>
    <axis xyz="0 0 0"/>
  </joint>
  <!--End Effector Attach Link-->
  <link name="end_effector_attach_link"/>
  <joint name="end_effector_attach_joint" type="fixed">
    <origin rpy="3.1416 0 3.1416" xyz="0 0 -0.02857"/>
    <parent link="fts_link"/>
    <child link="end_effector_attach_link"/>
  </joint>
  <!-- Missing inertial tags for now -->
  <link name="xlink_gripper_base">
    <visual>
      <origin rpy="0 0 0" xyz="0 0 0"/>
      <geometry>
        <mesh filename="package://xlink_gripper_description/meshes/visual/gripper_base.dae"/>
      </geometry>
    </visual>
    <collision>
      <origin rpy="0 0 0" xyz="0 0 0"/>
      <geometry>
        <mesh filename="package://xlink_gripper_description/meshes/collision/gripper_base.stl"/>
      </geometry>
    </collision>
    <inertial>
      <origin rpy="0 0 0" xyz="-0.003 0 0.073"/>
      <mass value="1.8"/>
      <inertia ixx="0.005" ixy="0" ixz="0" iyy="0.007" iyz="0" izz="0.005"/>
    </inertial>
  </link>
  <link name="xlink_gripper_edge"/>
  <joint name="xlink_gripper_edge_joint" type="fixed">
    <origin rpy="0 0 0" xyz="0 0 0.14935"/>
    <parent link="xlink_gripper_base"/>
    <child link="xlink_gripper_edge"/>
  </joint>
  <link name="gripper_manipulation_link"/>
  <joint name="gripper_manipulation_joint" type="fixed">
    <origin rpy="0 0 -1.570795" xyz="0 0 0.23"/>
    <parent link="xlink_gripper_base"/>
    <child link="gripper_manipulation_link"/>
  </joint>
  <link name="left_outer_link">
    <visual>
      <origin rpy="0 0 0" xyz="0 0 0"/>
      <geometry>
        <mesh filename="package://xlink_gripper_description/meshes/visual/outer_link.dae"/>
      </geometry>
    </visual>
    <collision>
      <origin rpy="0 0 0" xyz="0 0 0"/>
      <geometry>
        <mesh filename="package://xlink_gripper_description/meshes/collision/outer_link.stl"/>
      </geometry>
    </collision>
    <inertial>
      <origin rpy="0 0 0" xyz="-0.0014 0.0126 0"/>
      <mass value="0.03601900"/>
      <inertia ixx="0.00002119" ixy="0.00000374" ixz="0.0" iyy="0.00000317" iyz="0.0" izz="0.00002356"/>
    </inertial>
  </link>
  <link name="right_outer_link">
    <visual>
      <origin rpy="0 0 0" xyz="0 0 0"/>
      <geometry>
        <mesh filename="package://xlink_gripper_description/meshes/visual/outer_link.dae"/>
      </geometry>
    </visual>
    <collision>
      <origin rpy="0 0 0" xyz="0 0 0"/>
      <geometry>
        <mesh filename="package://xlink_gripper_description/meshes/collision/outer_link.stl"/>
      </geometry>
    </collision>
    <inertial>
      <origin rpy="0 0 0" xyz="-0.0014 0.0126 0"/>
      <mass value="0.03601900"/>
      <inertia ixx="0.00002119" ixy="0.00000374" ixz="0" iyy="0.00000317" iyz="0" izz="0.00002356"/>
    </inertial>
  </link>
  <link name="left_inner_link">
    <visual>
      <origin rpy="0 0 0" xyz="0 0 0"/>
      <geometry>
        <mesh filename="package://xlink_gripper_description/meshes/visual/inner_link.dae"/>
      </geometry>
    </visual>
    <collision>
      <origin rpy="0 0 0" xyz="0 0 0"/>
      <geometry>
        <mesh filename="package://xlink_gripper_description/meshes/collision/inner_link.stl"/>
      </geometry>
    </collision>
    <inertial>
      <origin rpy="0 0 0" xyz="0 0.04 -0.02"/>
      <mass value="0.0322428"/>
      <inertia ixx="0.0000280" ixy="0" ixz="0" iyy="0.0000198" iyz="0" izz="0.0000087"/>
    </inertial>
  </link>
  <link name="right_inner_link">
    <visual>
      <origin rpy="0 0 0" xyz="0 0 0"/>
      <geometry>
        <mesh filename="package://xlink_gripper_description/meshes/visual/inner_link.dae"/>
      </geometry>
    </visual>
    <collision>
      <origin rpy="0 0 0" xyz="0 0 0"/>
      <geometry>
        <mesh filename="package://xlink_gripper_description/meshes/collision/inner_link.stl"/>
      </geometry>
    </collision>
    <inertial>
      <origin rpy="0 0 0" xyz="0 0.04 -0.02"/>
      <mass value="0.0322428"/>
      <inertia ixx="0.0000280" ixy="0" ixz="0" iyy="0.0000198" iyz="0" izz="0.0000087"/>
    </inertial>
  </link>
  <link name="left_finger_link">
    <visual>
      <origin rpy="0 0 0" xyz="0 0 0"/>
      <geometry>
        <mesh filename="package://xlink_gripper_description/meshes/visual/basic_finger.dae"/>
      </geometry>
    </visual>
    <collision>
      <origin rpy="0 0 0" xyz="0 0 0"/>
      <geometry>
        <mesh filename="package://xlink_gripper_description/meshes/collision/basic_finger.stl"/>
      </geometry>
    </collision>
    <inertial>
      <origin rpy="0 0 0" xyz="-0.025750 0.011426 -0.000002"/>
      <mass value="0.0618"/>
      <inertia ixx="0.000016" ixy="-0.000006" ixz="0" iyy="0.000016" iyz="0" izz="0.000020"/>
    </inertial>
  </link>
  <link name="right_finger_link">
    <visual>
      <origin rpy="0 0 0" xyz="0 0 0"/>
      <geometry>
        <mesh filename="package://xlink_gripper_description/meshes/visual/basic_finger.dae"/>
      </geometry>
    </visual>
    <collision>
      <origin rpy="0 0 0" xyz="0 0 0"/>
      <geometry>
        <mesh filename="package://xlink_gripper_description/meshes/collision/basic_finger.stl"/>
      </geometry>
    </collision>
    <inertial>
      <origin rpy="0 0 0" xyz="-0.025750 0.011426 -0.000002"/>
      <mass value="0.0618"/>
      <inertia ixx="0.000016" ixy="-0.000006" ixz="0" iyy="0.000016" iyz="0" izz="0.000020"/>
    </inertial>
  </link>
  <joint name="gripper_base_joint" type="fixed">
    <origin rpy="0 0 0" xyz="0 0 0"/>
    <parent link="end_effector_attach_link"/>
    <child link="xlink_gripper_base"/>
  </joint>
  <joint name="gripper_joint" type="revolute">
    <origin rpy="1.5707 0 1.5707" xyz="0 0.0434975 0.12192"/>
    <parent link="xlink_gripper_base"/>
    <child link="left_outer_link"/>
    <axis xyz="0 0 -1"/>
    <limit effort="500.0" lower="0" upper="0.82" velocity="1.0"/>
    <dynamics damping="20.0" friction="4.0"/>
  </joint>
  <joint name="right_outer_joint" type="revolute">
    <mimic joint="gripper_joint"/>
    <origin rpy="1.5707 0 -1.5707" xyz="0 -0.0434975 0.12192"/>
    <parent link="xlink_gripper_base"/>
    <child link="right_outer_link"/>
    <axis xyz="0 0 -1"/>
    <limit effort="500.0" lower="0" upper="0.82" velocity="1.0"/>
    <dynamics damping="20.0" friction="4.0"/>
  </joint>
  <joint name="left_inner_joint" type="revolute">
    <mimic joint="gripper_joint"/>
    <origin rpy="1.5707 0 -1.5707" xyz="-0.0184836 0.0069826 0.1267273"/>
    <parent link="xlink_gripper_base"/>
    <child link="left_inner_link"/>
    <axis xyz="0 0 1"/>
    <limit effort="500.0" lower="0" upper="0.82" velocity="1.0"/>
    <dynamics damping="20.0" friction="4.0"/>
  </joint>
  <joint name="right_inner_joint" type="revolute">
    <mimic joint="gripper_joint"/>
    <origin rpy="1.5707 0 1.5707" xyz="0.0184836 -0.0069826 0.1267273"/>
    <parent link="xlink_gripper_base"/>
    <child link="right_inner_link"/>
    <axis xyz="0 0 1"/>
    <limit effort="500.0" lower="0" upper="0.82" velocity="1.0"/>
    <dynamics damping="20.0" friction="4.0"/>
  </joint>
  <joint name="left_finger_joint" type="revolute">
    <mimic joint="gripper_joint"/>
    <origin rpy="0 0 0" xyz="-.0003151 .0603242 0"/>
    <parent link="left_outer_link"/>
    <child link="left_finger_link"/>
    <axis xyz="0 0 1"/>
    <limit effort="500.0" lower="0" upper="0.82" velocity="1.0"/>
    <dynamics damping="20.0" friction="4.0"/>
  </joint>
  <joint name="right_finger_joint" type="revolute">
    <mimic joint="gripper_joint"/>
    <origin rpy="0 0 0" xyz="-.0003151 .0603242 0"/>
    <parent link="right_outer_link"/>
    <child link="right_finger_link"/>
    <axis xyz="0 0 1"/>
    <limit effort="500.0" lower="0" upper="0.82" velocity="1.0"/>
    <dynamics damping="20.0" friction="4.0"/>
  </joint>

  <!-- Rafti fingers -->
<!--  <link name="left_rafti_finger_link">-->
<!--    <visual>-->
<!--      <origin rpy="0 0 0" xyz="0 0 0" />-->
<!--      <geometry>-->
<!--        <mesh-->
<!--          filename="package://atomos_xlink_hw_config/description/assets/xlink_rafti_finger.stl" />-->
<!--      </geometry>-->
<!--      <material name="black" />-->
<!--    </visual>-->
<!--    <collision>-->
<!--      <origin rpy="0 0 0" xyz="0 0 0" />-->
<!--      <geometry>-->
<!--        <mesh-->
<!--          filename="package://atomos_xlink_hw_config/description/assets/xlink_rafti_finger.stl" />-->
<!--      </geometry>-->
<!--    </collision>-->
<!--  </link>-->
<!--  <link name="right_rafti_finger_link">-->
<!--    <visual>-->
<!--      <origin rpy="0 0 0" xyz="0 0 0" />-->
<!--      <geometry>-->
<!--        <mesh-->
<!--          filename="package://atomos_xlink_hw_config/description/assets/xlink_rafti_finger.stl" />-->
<!--      </geometry>-->
<!--      <material name="black" />-->
<!--    </visual>-->
<!--    <collision>-->
<!--      <origin rpy="0 0 0" xyz="0 0 0" />-->
<!--      <geometry>-->
<!--        <mesh-->
<!--          filename="package://atomos_xlink_hw_config/description/assets/xlink_rafti_finger.stl" />-->
<!--      </geometry>-->
<!--    </collision>-->
<!--  </link>-->
<!--  <joint name="left_rafti_finger_joint" type="fixed">-->
<!--    <origin rpy="3.14259 0 0" xyz="0 0 0" />-->
<!--    <parent link="left_finger_link" />-->
<!--    <child link="left_rafti_finger_link" />-->
<!--  </joint>-->
<!--  <joint name="right_rafti_finger_joint" type="fixed">-->
<!--    <origin rpy="3.14259 0 0" xyz="0 0 0" />-->
<!--    <parent link="right_finger_link" />-->
<!--    <child link="right_rafti_finger_link" />-->
<!--  </joint>-->
  <!-- Moveit Studio requires a link name called manual_grasp_link to perform quick tasks such as
  inspect surface -->
  <link name="manual_grasp_link" />
  <joint name="manual_grasp_joint" type="fixed">
    <parent link="gripper_manipulation_link" />
    <child link="manual_grasp_link" />
    <origin rpy="0 0 0" xyz="0 0 0" />
  </joint>
  <link name="grasp_link" />
  <joint name="grasp_joint" type="fixed">
    <parent link="gripper_manipulation_link" />
    <child link="grasp_link" />
    <origin rpy="0 0 0" xyz="0 0 0" />
  </joint>

  <!-- camera calibration tool-->
  <link name="calibration_tool_link">
    <visual>
      <geometry>
        <mesh
          filename="file://$(find atomos_xlink_hw_config)/description/assets/calibration_tool.stl" />
      </geometry>
    </visual>
    <collision>
      <geometry>
        <mesh
          filename="file://$(find atomos_xlink_hw_config)/description/assets/calibration_tool.stl" />
      </geometry>
    </collision>
  </link>
  <joint name="calibration_tool_joint" type="fixed">
    <parent link="grasp_link" />
    <child link="calibration_tool_link" />
    <origin xyz="0 0 0.011" rpy="0 0 0" />
  </joint>

  <!-- zed camera calibration pose-->
  <link name="estimated_zed_base_frame" />
  <joint name="estimated_zed_base_frame_joint" type="fixed">
    <parent link="servicer_sled_link" />
    <child link="estimated_zed_base_frame" />
    <!-- <origin xyz="-0.035 -0.39 0.24" rpy="0 0 0" /> -->
    <!--<origin xyz="-0.050 -0.37 0.24" rpy="0 0 0" />-->
    <origin rpy="0 0 0" xyz="-0.024939 -0.37902 0.21445" />
  </joint>

  <!-- zed camera URDF-->
    <material name="zed_mat">
      <color rgba="0.8 0.8 0.8 1.0" />
    </material>
    <material name="zedm_mat">
      <color rgba="0 0 0 1.0" />
    </material>
    <material name="zed2_mat">
      <color rgba="0.25 0.25 0.25 1.0" />
    </material>
    <material name="zed2i_mat">
      <color rgba="0.25 0.25 0.25 1.0" />
    </material>
    <material name="zedx_mat">
      <color rgba="0.25 0.25 0.25 1.0" />
    </material>
    <material name="zedxm_mat">
      <color rgba="0.25 0.25 0.25 1.0" />
    </material>
    <material name="virtual_mat">
      <color rgba="0.25 0.25 0.25 1.0" />
    </material>
    <material name="zedxonegs_mat">
      <color rgba="0.25 0.25 0.25 1.0" />
    </material>
    <material name="zedxone4k_mat">
      <color rgba="0.25 0.25 0.25 1.0" />
    </material> <!-- Camera mounting point (the threaded
    screw hole in the bottom) -->
    <link name="zed_camera_link" /> <!-- Camera Center -->
    <link name="zed_camera_center">
      <visual>
        <origin rpy="0 0 0" xyz="-0.01 0 0.0" />
        <geometry>
          <mesh filename="package://zed_msgs/meshes/zed2i.stl" />
        </geometry>
        <material name="zed2i_mat" />
      </visual>
      <collision>
        <origin rpy="0 0 0" xyz="-0.01 0 0.0" />
        <geometry>
          <mesh filename="package://zed_msgs/meshes/zed2i.stl" />
        </geometry>
      </collision>
    </link>
    <joint name="parent_zed_camera_link_joint" type="fixed">
      <parent link="estimated_zed_base_frame" />
      <child link="zed_camera_link" />
      <origin rpy="0 0 0" xyz="0 0 0" />
    </joint>
    <joint name="zed_camera_center_joint" type="fixed">
      <parent link="zed_camera_link" />
      <child link="zed_camera_center" />
      <origin rpy="0 0.0 0" xyz="0 0 0.015" />
    </joint> <!-- Left Camera -->
    <link name="zed_left_camera_frame" />
    <joint name="zed_left_camera_joint" type="fixed">
      <parent link="zed_camera_center" />
      <child link="zed_left_camera_frame" />
      <origin rpy="0 0 0" xyz="-0.01 0.06 0" />
    </joint>
    <link name="zed_left_camera_optical_frame" />
    <joint name="zed_left_camera_optical_joint" type="fixed">
      <origin rpy="-1.5707963267948966 0.0 -1.5707963267948966" xyz="0 0 0" />
      <parent link="zed_left_camera_frame" />
      <child link="zed_left_camera_optical_frame" />
    </joint> <!-- Right Camera -->
    <link name="zed_right_camera_frame" />
    <joint name="zed_right_camera_joint" type="fixed">
      <parent link="zed_camera_center" />
      <child link="zed_right_camera_frame" />
      <origin rpy="0 0 0" xyz="-0.01 -0.06 0" />
    </joint>
    <link name="zed_right_camera_optical_frame" />
    <joint name="zed_right_camera_optical_joint" type="fixed">
      <origin rpy="-1.5707963267948966 0.0 -1.5707963267948966" xyz="0 0 0" />
      <parent link="zed_right_camera_frame" />
      <child link="zed_right_camera_optical_frame" />
    </joint>

<!-- Environment -->
  <link name="floor">
    <visual>
      <origin rpy="0 0 0" xyz="0 0 0" />
      <geometry>
        <box size="4.0 4.0 0.2" />
      </geometry>
      <material name="transparent_blue">
        <color rgba="0 0 1 0.3"/>
      </material>
    </visual>
    <collision>
      <origin rpy="0 0 0" xyz="0 0 0" />
      <geometry>
        <box size="4.0 4.0 0.2" />
      </geometry>
    </collision>
  </link>
  <joint name="floor_joint" type="fixed">
    <parent link="servicer_sled_link" />
    <child link="floor" />
      <origin rpy="0 0 0" xyz="0 0 -0.57" />
  </joint>

  <link name="back">
    <visual>
      <origin rpy="0 0 0" xyz="0 0 0" />
      <material name="transparent_blue">
        <color rgba="0 0 1 0.3"/>
      </material>
      <geometry>
        <box size="0.2 2.0 2.0" />
      </geometry>
    </visual>
    <collision>
      <origin rpy="0 0 0" xyz="0 0 0" />
      <geometry>
        <box size="0.2 2.0 2.0" />
      </geometry>
    </collision>
  </link>
  <joint name="back_joint" type="fixed">
    <parent link="servicer_sled_link" />
    <child link="back" />
      <origin rpy="0 0 0" xyz="-0.11 0 0" />
  </joint>

  <link name="tank_air_hoses">
    <visual>
      <origin rpy="0 0 0" xyz="0 0 0" />
      <geometry>
        <box size="0.15 0.15 0.15" />
      </geometry>1
    </visual>
    <collision>
      <origin rpy="0 0 0" xyz="0 0 0" />
      <geometry>
        <box size="0.15 0.15 0.15" />
      </geometry>
    </collision>
  </link>
  <joint name="tank_air_hoses_joint" type="fixed">
    <parent link="servicer_sled_link" />
    <child link="tank_air_hoses" />
      <origin rpy="0 0 0" xyz="0.26 -0.38 -0.33" />
  </joint>

  <ros2_control name="xlink_system" type="system">
    <hardware>
      <plugin>xlink_core_hardware/xLinkSystem</plugin>
      <!-- <plugin>mock_components/GenericSystem</plugin> -->
      <param name="bus_device">/dev/ttyUSB0</param>
      <param name="baud_rate">1000000</param>
      <param name="parity">O</param>
      <!-- Add the joint ids here, should be of the form "int,int,int" etc -->
      <param name="joint_ids">17,51,46,39,24,14,19</param>
      <!-- FTS ID-->
      <param name="fts_id">2</param>
      <param name="fts_frame">fts_link</param>
      <param name="has_gripper">True</param>
      <param name="gripper_id">58</param>
      <param name="control_mode">POSVEL</param>
    </hardware>
    <joint name="joint_1">
      <command_interface name="position">
        <param name="min">-2.8798</param>
        <param name="max">2.8798</param>
      </command_interface>
      <command_interface name="velocity">
        <param name="min">-0.3</param>
        <param name="max">0.3</param>
      </command_interface>
      <state_interface name="position" />
      <state_interface name="velocity" />
      <state_interface name="effort" />
    </joint>
    <joint name="joint_2">
      <command_interface name="position">
        <param name="min">-2.8798</param>
        <param name="max">2.8798</param>
      </command_interface>
      <command_interface name="velocity">
        <param name="min">-0.3</param>
        <param name="max">0.3</param>
      </command_interface>
      <state_interface name="position" />
      <state_interface name="velocity" />
      <state_interface name="effort" />
    </joint>
    <joint name="joint_3">
      <command_interface name="position">
        <param name="min">-3.2289</param>
        <param name="max">2.5307</param>
      </command_interface>
      <command_interface name="velocity">
        <param name="min">-0.3</param>
        <param name="max">0.3</param>
      </command_interface>
      <state_interface name="position" />
      <state_interface name="velocity" />
      <state_interface name="effort" />
    </joint>
    <joint name="joint_4">
      <command_interface name="position">
        <param name="min">-2.8798</param>
        <param name="max">2.8798</param>
      </command_interface>
      <command_interface name="velocity">
        <param name="min">-0.3</param>
        <param name="max">0.3</param>
      </command_interface>
      <state_interface name="position" />
      <state_interface name="velocity" />
      <state_interface name="effort" />
    </joint>
    <joint name="joint_5">
      <command_interface name="position">
        <param name="min">-3.927</param>
        <param name="max">1.8326</param>
      </command_interface>
      <command_interface name="velocity">
        <param name="min">-0.3</param>
        <param name="max">0.3</param>
      </command_interface>
      <state_interface name="position" />
      <state_interface name="velocity" />
      <state_interface name="effort" />
    </joint>
    <joint name="joint_6">
      <command_interface name="position">
        <param name="min">-3.2289</param>
        <param name="max">2.5307</param>
      </command_interface>
      <command_interface name="velocity">
        <param name="min">-0.3</param>
        <param name="max">0.3</param>
      </command_interface>
      <state_interface name="position" />
      <state_interface name="velocity" />
      <state_interface name="effort" />
    </joint>
    <joint name="joint_7">
      <command_interface name="position">
        <param name="min">-1.8326</param>
        <param name="max">3.927</param>
      </command_interface>
      <command_interface name="velocity">
        <param name="min">-0.3</param>
        <param name="max">0.3</param>
      </command_interface>
      <state_interface name="position" />
      <state_interface name="velocity" />
      <state_interface name="effort" />
    </joint>
    <joint name="gripper_joint">
      <command_interface name="position">
        <param name="min">0.0</param>
        <param name="max">1.0</param>
      </command_interface>
      <state_interface name="position" />
      <state_interface name="velocity" />
      <state_interface name="effort" />
    </joint>
    <sensor name="xlink_fts">
      <state_interface name="force.x" />
      <state_interface name="force.y" />
      <state_interface name="force.z" />
      <state_interface name="torque.x" />
      <state_interface name="torque.y" />
      <state_interface name="torque.z" />
    </sensor>
  </ros2_control>
</robot>
