<?xml version="1.0"?>
<!-- =================================================================================== -->
<!-- |    This document was autogenerated by xacro from motiv_xlink_moveit_studio.hw.xacro | -->
<!-- |    EDITING THIS FILE BY HAND IS NOT RECOMMENDED                                 | -->
<!-- =================================================================================== -->
<robot name="xlink">
  <!-- Create servicer sled -->
  <link name="servicer_sled_link">
    <visual>
      <geometry>
        <mesh filename="file://$(find atomos_xlink_hw_config)/description/assets/craft.stl"
          scale="0.1 0.1 0.1" />/> </geometry>
    </visual>
  </link>
  <joint name="servicer_sled_joint" type="fixed">
    <parent link="world" />
    <child link="servicer_sled_link" />
    <origin xyz="0 0 0" rpy="0 0 0" />
  </joint>
  <!-- Create world link -->
  <link name="world" />
  <!-- Material Color Definitions -->
  <material name="grey">
    <color rgba="0.6 0.6 0.6 1" />
  </material>
  <!-- LINKS -->
  <link name="base_link">
    <inertial>
      <origin rpy="0 0 0" xyz="-0.0009 0.0005 0.0465" />
      <mass value="0.7823" />
      <inertia ixx=".0034" ixy="0" ixz="0" iyy=".0034" iyz="0" izz="0.0032" />
    </inertial>
    <visual>
      <origin rpy="0 0 0" xyz="0 0 0" />
      <geometry>
        <mesh
          filename="file:///home/rlprattpop22/user_ws/install/xlink_description/share/xlink_description/meshes/visual/base_link.dae" />
      </geometry>
    </visual>
    <collision>
      <origin rpy="0 0 0" xyz="0 0 0" />
      <geometry>
        <mesh
          filename="file:///home/rlprattpop22/user_ws/install/xlink_description/share/xlink_description/meshes/collision/base_link.stl" />
      </geometry>
    </collision>
  </link>
  <link name="link_1">
    <inertial>
      <origin rpy="0 0 0" xyz="-.0264 .0005 .1719" />
      <mass value="5.5103" />
      <inertia ixx=".4537" ixy=".0002" ixz="-.0140" iyy=".3039" iyz="0" izz=".3996" />
    </inertial>
    <visual>
      <origin rpy="0 0 0" xyz="0 0 0" />
      <geometry>
        <mesh
          filename="file:///home/rlprattpop22/user_ws/install/xlink_description/share/xlink_description/meshes/visual/link_1.dae" />
      </geometry>
    </visual>
    <collision>
      <origin rpy="0 0 0" xyz="0 0 0" />
      <geometry>
        <mesh
          filename="file:///home/rlprattpop22/user_ws/install/xlink_description/share/xlink_description/meshes/collision/link_1.stl" />
      </geometry>
    </collision>
  </link>
  <link name="link_2">
    <inertial>
      <origin rpy="0 0 0" xyz=".0296 0 .1393" />
      <mass value=".5943" />
      <inertia ixx=".0014" ixy="0" ixz=".0002" iyy=".0012" iyz="0" izz=".0016" />
    </inertial>
    <visual>
      <origin rpy="0 0 0" xyz="0 0 0" />
      <geometry>
        <mesh
          filename="file:///home/rlprattpop22/user_ws/install/xlink_description/share/xlink_description/meshes/visual/link_2.dae" />
      </geometry>
    </visual>
    <collision>
      <origin rpy="0 0 0" xyz="0 0 0" />
      <geometry>
        <mesh
          filename="file:///home/rlprattpop22/user_ws/install/xlink_description/share/xlink_description/meshes/collision/link_2.stl" />
      </geometry>
    </collision>
  </link>
  <link name="link_3">
    <inertial>
      <origin rpy="0 0 0" xyz=".0247 -.0005 .2285" />
      <mass value="5.3096" />
      <inertia ixx=".1119" ixy=".0002" ixz=".0125" iyy=".0706" iyz="-.0001" izz=".0628" />
    </inertial>
    <visual>
      <origin rpy="0 0 0" xyz="0 0 0" />
      <geometry>
        <mesh
          filename="file:///home/rlprattpop22/user_ws/install/xlink_description/share/xlink_description/meshes/visual/link_3.dae" />
      </geometry>
    </visual>
    <collision>
      <origin rpy="0 0 0" xyz="0 0 0" />
      <geometry>
        <mesh
          filename="file:///home/rlprattpop22/user_ws/install/xlink_description/share/xlink_description/meshes/collision/link_3.stl" />
      </geometry>
    </collision>
  </link>
  <link name="link_4">
    <inertial>
      <origin rpy="0 0 0" xyz=".0273 0 .1364" />
      <mass value=".5653" />
      <inertia ixx=".0013" ixy="0" ixz=".0002" iyy=".001" iyz="0" izz=".0014" />
    </inertial>
    <visual>
      <origin rpy="0 0 0" xyz="0 0 0" />
      <geometry>
        <mesh
          filename="file:///home/rlprattpop22/user_ws/install/xlink_description/share/xlink_description/meshes/visual/link_4.dae" />
      </geometry>
    </visual>
    <collision>
      <origin rpy="0 0 0" xyz="0 0 0" />
      <geometry>
        <mesh
          filename="file:///home/rlprattpop22/user_ws/install/xlink_description/share/xlink_description/meshes/collision/link_4.stl" />
      </geometry>
    </collision>
  </link>
  <link name="link_5">
    <inertial>
      <origin rpy="0 0 0" xyz="-.0247 .0005 .2254" />
      <mass value="5.3096" />
      <inertia ixx=".1119" ixy=".0002" ixz="-.0125" iyy=".0706" iyz="0.0001" izz=".0628" />
    </inertial>
    <visual>
      <origin rpy="0 0 0" xyz="0 0 0" />
      <geometry>
        <mesh
          filename="file:///home/rlprattpop22/user_ws/install/xlink_description/share/xlink_description/meshes/visual/link_5.dae" />
      </geometry>
    </visual>
    <collision>
      <origin rpy="0 0 0" xyz="0 0 0" />
      <geometry>
        <mesh
          filename="file:///home/rlprattpop22/user_ws/install/xlink_description/share/xlink_description/meshes/collision/link_5.stl" />
      </geometry>
    </collision>
  </link>
  <link name="link_6">
    <inertial>
      <origin rpy="0 0 0" xyz=".0273 0 .1364" />
      <mass value=".5653" />
      <inertia ixx=".0013" ixy="0" ixz="0.0002" iyy="0.001" iyz="0" izz=".0014" />
    </inertial>
    <visual>
      <origin rpy="0 0 0" xyz="0 0 0" />
      <geometry>
        <mesh
          filename="file:///home/rlprattpop22/user_ws/install/xlink_description/share/xlink_description/meshes/visual/link_6.dae" />
      </geometry>
    </visual>
    <collision>
      <origin rpy="0 0 0" xyz="0 0 0" />
      <geometry>
        <mesh
          filename="file:///home/rlprattpop22/user_ws/install/xlink_description/share/xlink_description/meshes/collision/link_6.stl" />
      </geometry>
    </collision>
  </link>
  <link name="link_7">
    <inertial>
      <origin rpy="0 0 0" xyz="0 .0014 .1629" />
      <mass value="3.6704" />
      <inertia ixx=".2818" ixy="-.0197" ixz=".0011" iyy=".2795" iyz="-.0007" izz=".5235" />
    </inertial>
    <visual>
      <origin rpy="0 0 0" xyz="0 0 0" />
      <geometry>
        <mesh
          filename="file:///home/rlprattpop22/user_ws/install/xlink_description/share/xlink_description/meshes/visual/link_7.dae" />
      </geometry>
    </visual>
    <collision>
      <origin rpy="0 0 0" xyz="0 0 0" />
      <geometry>
        <mesh
          filename="file:///home/rlprattpop22/user_ws/install/xlink_description/share/xlink_description/meshes/collision/link_7.stl" />
      </geometry>
    </collision>
  </link>
  <!-- JOINTS -->
  <!-- Dynamics and velocity limits are placeholders -->
  <joint name="base_joint" type="fixed">
    <origin rpy="-1.5707963267948966 0.0 -1.5707963267948966" xyz="0 0 0" />
    <parent link="servicer_sled_link" />
    <child link="base_link" />
  </joint>
  <joint name="joint_1" type="revolute">
    <origin rpy="0 0 0" xyz="0 0 0.111" />
    <parent link="base_link" />
    <child link="link_1" />
    <axis xyz="0 0 1" />
    <limit effort="250" lower="-2.8798" upper="2.8798" velocity="0.2" />
    <dynamics damping="20.0" friction="4.0" />
  </joint>
  <joint name="joint_2" type="revolute">
    <origin rpy="3.1416 -1.5708 3.1416" xyz="0 0 0.276" />
    <parent link="link_1" />
    <child link="link_2" />
    <axis xyz="0 0 1" />
    <limit effort="250" lower="-2.8798" upper="2.8798" velocity="0.2" />
    <dynamics damping="20.0" friction="4.0" />
  </joint>
  <joint name="joint_3" type="revolute">
    <origin rpy="0 1.5708 0" xyz="0 0 0.159" />
    <parent link="link_2" />
    <child link="link_3" />
    <axis xyz="0 0 1" />
    <limit effort="120" lower="-3.2289" upper="2.5307" velocity="0.3" />
    <dynamics damping="20.0" friction="4.0" />
  </joint>
  <joint name="joint_4" type="revolute">
    <origin rpy="0 -1.5708 3.1416" xyz="0 0 0.32809" />
    <parent link="link_3" />
    <child link="link_4" />
    <axis xyz="0 0 1" />
    <limit effort="120" lower="-2.8798" upper="2.8798" velocity="0.3" />
    <dynamics damping="20.0" friction="4.0" />
  </joint>
  <joint name="joint_5" type="revolute">
    <origin rpy="0 -1.5708 3.1416" xyz="0 0 0.155" />
    <parent link="link_4" />
    <child link="link_5" />
    <axis xyz="0 0 1" />
    <limit effort="120" lower="-3.927" upper="1.8326" velocity="0.3" />
    <dynamics damping="20.0" friction="4.0" />
  </joint>
  <joint name="joint_6" type="revolute">
    <origin rpy="2.93874 -1.5708 -2.93874" xyz="0 0 0.325" />
    <parent link="link_5" />
    <child link="link_6" />
    <axis xyz="0 0 1" />
    <limit effort="120" lower="-3.2289" upper="2.5307" velocity="0.3" />
    <dynamics damping="20.0" friction="4.0" />
  </joint>
  <joint name="joint_7" type="revolute">
    <origin rpy="0 1.5708 0" xyz="0 0 0.155" />
    <parent link="link_6" />
    <child link="link_7" />
    <axis xyz="0 0 1" />
    <limit effort="120" lower="-1.8326" upper="3.927" velocity="0.3" />
    <dynamics damping="20.0" friction="4.0" />
  </joint>
  <!--Force/Torque
  Sensor Link-->
  <link name="fts_link">
    <inertial>
      <origin rpy="0 0 0" xyz="0 0 0" />
      <mass value="0.01" />
      <inertia ixx="1e-6" ixy="0" ixz="0" iyy="1e-6" iyz="0" izz="1e-6" />
    </inertial>
  </link>
  <!--Force/Torque
  Sensor Joint-->
  <joint name="fts_joint" type="fixed">
    <origin rpy="3.1416 0 1.5708" xyz="0 0 0.26643" />
    <parent link="link_7" />
    <child link="fts_link" />
    <axis xyz="0 0 0" />
  </joint>
  <material name="xlink_gray">
    <color rgba="0.3 0.3 0.3 1" />
  </material>
  <!-- Missing inertial tags for now -->
  <link name="xlink_gripper_base">
    <visual>
      <origin rpy="0 0 0" xyz="0 0 0" />
      <geometry>
        <mesh
          filename="file:///home/rlprattpop22/user_ws/install/xlink_gripper_description/share/xlink_gripper_description/meshes/visual/gripper_base.dae" />
      </geometry>
      <material name="xlink_gray" />
    </visual>
    <collision>
      <origin rpy="0 0 0" xyz="0 0 0" />
      <geometry>
        <mesh
          filename="file:///home/rlprattpop22/user_ws/install/xlink_gripper_description/share/xlink_gripper_description/meshes/collision/gripper_base.stl" />
      </geometry>
    </collision>
    <inertial>
      <origin rpy="0 0 0" xyz="-0.003 0 0.073" />
      <mass value="1.8" />
      <inertia ixx="0.005" ixy="0" ixz="0" iyy="0.007" iyz="0" izz="0.005" />
    </inertial>
  </link>
  <link name="gripper_manipulation_link" />
  <joint name="gripper_manipulation_joint" type="fixed">
    <origin rpy="0 0 -1.570795" xyz="0 0 0.23" />
    <parent link="xlink_gripper_base" />
    <child link="gripper_manipulation_link" />
  </joint>
  <link name="left_outer_link">
    <visual>
      <origin rpy="0 0 0" xyz="0 0 0" />
      <geometry>
        <mesh
          filename="file:///home/rlprattpop22/user_ws/install/xlink_gripper_description/share/xlink_gripper_description/meshes/visual/outer_link.dae" />
      </geometry>
      <material name="xlink_gray" />
    </visual>
    <collision>
      <origin rpy="0 0 0" xyz="0 0 0" />
      <geometry>
        <mesh
          filename="file:///home/rlprattpop22/user_ws/install/xlink_gripper_description/share/xlink_gripper_description/meshes/collision/outer_link.stl" />
      </geometry>
    </collision>
    <inertial>
      <origin rpy="0 0 0" xyz="-0.0014 0.0126 0" />
      <mass value="0.03601900" />
      <inertia ixx="0.00002119" ixy="0.00000374" ixz="0.0" iyy="0.00000317" iyz="0.0"
        izz="0.00002356" />
    </inertial>
  </link>
  <link name="right_outer_link">
    <visual>
      <origin rpy="0 0 0" xyz="0 0 0" />
      <geometry>
        <mesh
          filename="file:///home/rlprattpop22/user_ws/install/xlink_gripper_description/share/xlink_gripper_description/meshes/visual/outer_link.dae" />
      </geometry>
      <material name="xlink_gray" />
    </visual>
    <collision>
      <origin rpy="0 0 0" xyz="0 0 0" />
      <geometry>
        <mesh
          filename="file:///home/rlprattpop22/user_ws/install/xlink_gripper_description/share/xlink_gripper_description/meshes/collision/outer_link.stl" />
      </geometry>
    </collision>
    <inertial>
      <origin rpy="0 0 0" xyz="-0.0014 0.0126 0" />
      <mass value="0.03601900" />
      <inertia ixx="0.00002119" ixy="0.00000374" ixz="0" iyy="0.00000317" iyz="0" izz="0.00002356" />
    </inertial>
  </link>
  <link name="left_inner_link">
    <visual>
      <origin rpy="0 0 0" xyz="0 0 0" />
      <geometry>
        <mesh
          filename="file:///home/rlprattpop22/user_ws/install/xlink_gripper_description/share/xlink_gripper_description/meshes/visual/inner_link.dae" />
      </geometry>
      <material name="xlink_gray" />
    </visual>
    <collision>
      <origin rpy="0 0 0" xyz="0 0 0" />
      <geometry>
        <mesh
          filename="file:///home/rlprattpop22/user_ws/install/xlink_gripper_description/share/xlink_gripper_description/meshes/collision/inner_link.stl" />
      </geometry>
    </collision>
    <inertial>
      <origin rpy="0 0 0" xyz="0 0.04 -0.02" />
      <mass value="0.0322428" />
      <inertia ixx="0.0000280" ixy="0" ixz="0" iyy="0.0000198" iyz="0" izz="0.0000087" />
    </inertial>
  </link>
  <link name="right_inner_link">
    <visual>
      <origin rpy="0 0 0" xyz="0 0 0" />
      <geometry>
        <mesh
          filename="file:///home/rlprattpop22/user_ws/install/xlink_gripper_description/share/xlink_gripper_description/meshes/visual/inner_link.dae" />
      </geometry>
      <material name="xlink_gray" />
    </visual>
    <collision>
      <origin rpy="0 0 0" xyz="0 0 0" />
      <geometry>
        <mesh
          filename="file:///home/rlprattpop22/user_ws/install/xlink_gripper_description/share/xlink_gripper_description/meshes/collision/inner_link.stl" />
      </geometry>
    </collision>
    <inertial>
      <origin rpy="0 0 0" xyz="0 0.04 -0.02" />
      <mass value="0.0322428" />
      <inertia ixx="0.0000280" ixy="0" ixz="0" iyy="0.0000198" iyz="0" izz="0.0000087" />
    </inertial>
  </link>
  <link name="left_finger_link">
    <visual>
      <origin rpy="0 0 0" xyz="0 0 0" />
      <geometry>
        <mesh
          filename="file:///home/rlprattpop22/user_ws/install/xlink_gripper_description/share/xlink_gripper_description/meshes/visual/basic_finger.dae" />
      </geometry>
      <material name="xlink_gray" />
    </visual>
    <collision>
      <origin rpy="0 0 0" xyz="0 0 0" />
      <geometry>
        <mesh
          filename="file:///home/rlprattpop22/user_ws/install/xlink_gripper_description/share/xlink_gripper_description/meshes/collision/basic_finger.stl" />
      </geometry>
    </collision>
    <inertial>
      <origin rpy="0 0 0" xyz="-0.025750 0.011426 -0.000002" />
      <mass value="0.0618" />
      <inertia ixx="0.000016" ixy="-0.000006" ixz="0" iyy="0.000016" iyz="0" izz="0.000020" />
    </inertial>
  </link>
  <link name="right_finger_link">
    <visual>
      <origin rpy="0 0 0" xyz="0 0 0" />
      <geometry>
        <mesh
          filename="file:///home/rlprattpop22/user_ws/install/xlink_gripper_description/share/xlink_gripper_description/meshes/visual/basic_finger.dae" />
      </geometry>
      <material name="xlink_gray" />
    </visual>
    <collision>
      <origin rpy="0 0 0" xyz="0 0 0" />
      <geometry>
        <mesh
          filename="file:///home/rlprattpop22/user_ws/install/xlink_gripper_description/share/xlink_gripper_description/meshes/collision/basic_finger.stl" />
      </geometry>
    </collision>
    <inertial>
      <origin rpy="0 0 0" xyz="-0.025750 0.011426 -0.000002" />
      <mass value="0.0618" />
      <inertia ixx="0.000016" ixy="-0.000006" ixz="0" iyy="0.000016" iyz="0" izz="0.000020" />
    </inertial>
  </link>
  <joint name="gripper_base_joint" type="fixed">
    <origin rpy="0 3.141592653589793 0" xyz="0 0 -0.029" />
    <parent link="fts_link" />
    <child link="xlink_gripper_base" />
  </joint>
  <joint name="gripper_joint" type="revolute">
    <origin rpy="1.5707 0 1.5707" xyz="0 0.0434975 0.12192" />
    <parent link="xlink_gripper_base" />
    <child link="left_outer_link" />
    <axis xyz="0 0 -1" />
    <limit effort="500.0" lower="0" upper="1.0" velocity="1.0" />
    <dynamics damping="20.0" friction="4.0" />
  </joint>
  <joint name="right_outer_joint" type="revolute">
    <mimic joint="gripper_joint" />
    <origin rpy="1.5707 0 -1.5707" xyz="0 -0.0434975 0.12192" />
    <parent link="xlink_gripper_base" />
    <child link="right_outer_link" />
    <axis xyz="0 0 -1" />
    <limit effort="500.0" lower="0" upper="1.0" velocity="1.0" />
    <dynamics damping="20.0" friction="4.0" />
  </joint>
  <joint name="left_inner_joint" type="revolute">
    <mimic joint="gripper_joint" />
    <origin rpy="1.5707 0 -1.5707" xyz="-0.0184836 0.0069826 0.1267273" />
    <parent link="xlink_gripper_base" />
    <child link="left_inner_link" />
    <axis xyz="0 0 1" />
    <limit effort="500.0" lower="0" upper="1.0" velocity="1.0" />
    <dynamics damping="20.0" friction="4.0" />
  </joint>
  <joint name="right_inner_joint" type="revolute">
    <mimic joint="gripper_joint" />
    <origin rpy="1.5707 0 1.5707" xyz="0.0184836 -0.0069826 0.1267273" />
    <parent link="xlink_gripper_base" />
    <child link="right_inner_link" />
    <axis xyz="0 0 1" />
    <limit effort="500.0" lower="0" upper="1.0" velocity="1.0" />
    <dynamics damping="20.0" friction="4.0" />
  </joint>
  <joint name="left_finger_joint" type="revolute">
    <mimic joint="gripper_joint" />
    <origin rpy="0 0 0" xyz="-.0003151 .0603242 0" />
    <parent link="left_outer_link" />
    <child link="left_finger_link" />
    <axis xyz="0 0 1" />
    <limit effort="500.0" lower="0" upper="1.0" velocity="1.0" />
    <dynamics damping="20.0" friction="4.0" />
  </joint>
  <joint name="right_finger_joint" type="revolute">
    <mimic joint="gripper_joint" />
    <origin rpy="0 0 0" xyz="-.0003151 .0603242 0" />
    <parent link="right_outer_link" />
    <child link="right_finger_link" />
    <axis xyz="0 0 1" />
    <limit effort="500.0" lower="0" upper="1.0" velocity="1.0" />
    <dynamics damping="20.0" friction="4.0" />
  </joint>
  <!-- camera body, with origin at bottom screw mount -->
  <joint name="wrist_mounted_camera_joint" type="fixed">
    <origin rpy="0 -1.5707963267948966 -3.141592653589793" xyz="0.05305 0 0.1324385" />
    <parent link="xlink_gripper_base" />
    <child link="wrist_mounted_camera_bottom_screw_frame" />
  </joint>
  <link name="wrist_mounted_camera_bottom_screw_frame" />
  <joint name="wrist_mounted_camera_link_joint" type="fixed">
    <origin rpy="0 0 0" xyz="0 0.02 0.0115" />
    <parent link="wrist_mounted_camera_bottom_screw_frame" />
    <child link="wrist_mounted_camera_link" />
  </joint>
  <link name="wrist_mounted_camera_link">
    <visual>
      <origin rpy="1.5707963267948966 0 1.5707963267948966" xyz="0.00987 -0.02 0" />
      <geometry>
        <mesh filename="file:///opt/ros/humble/share/realsense2_description/meshes/d415.stl" />
      </geometry>
      <material name="aluminum" />
    </visual>
    <collision>
      <origin rpy="0 0 0" xyz="0 -0.02 0" />
      <geometry>
        <box size="0.02005 0.099 0.023" />
      </geometry>
    </collision>
    <inertial>
      <mass value="0.072" />
      <!-- The following are not reliable values, and should not be used for modeling -->
      <origin xyz="0 0 0" />
      <inertia ixx="0.003881243" ixy="0.0" ixz="0.0" iyy="0.000498940" iyz="0.0" izz="0.003879257" />
    </inertial>
  </link>
  <!-- Moveit Studio requires a link name called manual_grasp_link to perform quick tasks such as
  inspect surface -->
  <link name="manual_grasp_link" />
  <joint name="manual_grasp_joint" type="fixed">
    <parent link="gripper_manipulation_link" />
    <child link="manual_grasp_link" />
    <origin rpy="0 0 0" xyz="0 0 0" />
  </joint>
  <link name="grasp_link" />
  <joint name="grasp_joint" type="fixed">
    <parent link="gripper_manipulation_link" />
    <child link="grasp_link" />
    <origin rpy="0 0 0" xyz="0 0 0" />
  </joint>

  <!-- camera calibration tool-->
  <link name="calibration_tool_link">
    <visual>
      <geometry>
        <mesh
          filename="file://$(find atomos_xlink_hw_config)/description/assets/calibration_tool.stl" />
      </geometry>
    </visual>
  </link>
  <joint name="calibration_tool_joint" type="fixed">
    <parent link="grasp_link" />
    <child link="calibration_tool_link" />
    <origin xyz="0 0 0.011" rpy="0 0 0" />
  </joint>

  <link name="calibration_tool_frame" />
  <joint name="calibration_tool_frame_joint" type="fixed">
    <parent link="calibration_tool_link" />
    <child link="calibration_tool_frame" />
    <origin xyz="0 -0.09325 -0.01" rpy="0 ${pi} ${pi}" />
  </joint>

  <!-- zed camera calibration pose-->
  <link name="estimated_zed_base_frame" />
  <joint name="estimated_zed_base_frame_joint" type="fixed">
    <parent link="base_link" />
    <child link="estimated_zed_base_frame" />
    <origin xyz="0.3 -0.2 -0.05" rpy="1.542 -1.542 0" />
  </joint>

  <!-- zed camera URDF-->
    <material name="zed_mat">
      <color rgba="0.8 0.8 0.8 1.0" />
    </material>
    <material name="zedm_mat">
      <color rgba="0 0 0 1.0" />
    </material>
    <material name="zed2_mat">
      <color rgba="0.25 0.25 0.25 1.0" />
    </material>
    <material name="zed2i_mat">
      <color rgba="0.25 0.25 0.25 1.0" />
    </material>
    <material name="zedx_mat">
      <color rgba="0.25 0.25 0.25 1.0" />
    </material>
    <material name="zedxm_mat">
      <color rgba="0.25 0.25 0.25 1.0" />
    </material>
    <material name="virtual_mat">
      <color rgba="0.25 0.25 0.25 1.0" />
    </material>
    <material name="zedxonegs_mat">
      <color rgba="0.25 0.25 0.25 1.0" />
    </material>
    <material name="zedxone4k_mat">
      <color rgba="0.25 0.25 0.25 1.0" />
    </material> <!-- Camera mounting point (the threaded
    screw hole in the bottom) -->
    <link name="zed_camera_link" /> <!-- Camera Center -->
    <link name="zed_camera_center">
      <visual>
        <origin rpy="0 0 0" xyz="-0.01 0 0.0" />
        <geometry>
          <mesh filename="file:///opt/ros/humble/share/zed_msgs/meshes/zed2i.stl" />
        </geometry>
        <material name="zed2i_mat" />
      </visual>
      <collision>
        <origin rpy="0 0 0" xyz="-0.01 0 0.0" />
        <geometry>
          <mesh filename="file:///opt/ros/humble/share/zed_msgs/meshes/zed2i.stl" />
        </geometry>
      </collision>
    </link>
    <joint name="parent_zed_camera_link_joint" type="fixed">
      <parent link="estimated_zed_base_frame" />
      <child link="zed_camera_link" />
      <origin rpy="0 0 0" xyz="0 0 0" />
    </joint>
    <joint name="zed_camera_center_joint" type="fixed">
      <parent link="zed_camera_link" />
      <child link="zed_camera_center" />
      <origin rpy="0 0.0 0" xyz="0 0 0.015" />
    </joint> <!-- Left Camera -->
    <link name="zed_left_camera_frame" />
    <joint name="zed_left_camera_joint" type="fixed">
      <parent link="zed_camera_center" />
      <child link="zed_left_camera_frame" />
      <origin rpy="0 0 0" xyz="-0.01 0.06 0" />
    </joint>
    <link name="zed_left_camera_optical_frame" />
    <joint name="zed_left_camera_optical_joint" type="fixed">
      <origin rpy="-1.5707963267948966 0.0 -1.5707963267948966" xyz="0 0 0" />
      <parent link="zed_left_camera_frame" />
      <child link="zed_left_camera_optical_frame" />
    </joint> <!-- Right Camera -->
    <link name="zed_right_camera_frame" />
    <joint name="zed_right_camera_joint" type="fixed">
      <parent link="zed_camera_center" />
      <child link="zed_right_camera_frame" />
      <origin rpy="0 0 0" xyz="-0.01 -0.06 0" />
    </joint>
    <link name="zed_right_camera_optical_frame" />
    <joint name="zed_right_camera_optical_joint" type="fixed">
      <origin rpy="-1.5707963267948966 0.0 -1.5707963267948966" xyz="0 0 0" />
      <parent link="zed_right_camera_frame" />
      <child link="zed_right_camera_optical_frame" />
    </joint>

  <ros2_control name="xlink_system" type="system">
    <hardware>
      <!-- <plugin>xlink_core_hardware/xLinkSystem</plugin> -->
      <plugin>mock_components/GenericSystem</plugin>
      <param name="bus_device">/dev/ttyUSB0</param>
      <param name="baud_rate">1000000</param>
      <param name="parity">O</param>
      <!-- Add the joint ids here, should be of the form "int,int,int" etc -->
      <param name="joint_ids">9,31,7,30,36,14,41</param>
      <!-- FTS ID-->
      <param name="fts_id">2</param>
      <param name="fts_frame">fts_link</param>
      <param name="has_gripper">True</param>
      <param name="gripper_id">6</param>
      <param name="control_mode">POSVEL</param>
    </hardware>
    <joint name="joint_1">
      <command_interface name="position">
        <param name="min">-2.8798</param>
        <param name="max">2.8798</param>
      </command_interface>
      <command_interface name="velocity">
        <param name="min">-0.3</param>
        <param name="max">0.3</param>
      </command_interface>
      <state_interface name="position" />
      <state_interface name="velocity" />
      <state_interface name="effort" />
    </joint>
    <joint name="joint_2">
      <command_interface name="position">
        <param name="min">-2.8798</param>
        <param name="max">2.8798</param>
      </command_interface>
      <command_interface name="velocity">
        <param name="min">-0.3</param>
        <param name="max">0.3</param>
      </command_interface>
      <state_interface name="position" />
      <state_interface name="velocity" />
      <state_interface name="effort" />
    </joint>
    <joint name="joint_3">
      <command_interface name="position">
        <param name="min">-3.2289</param>
        <param name="max">2.5307</param>
      </command_interface>
      <command_interface name="velocity">
        <param name="min">-0.3</param>
        <param name="max">0.3</param>
      </command_interface>
      <state_interface name="position" />
      <state_interface name="velocity" />
      <state_interface name="effort" />
    </joint>
    <joint name="joint_4">
      <command_interface name="position">
        <param name="min">-2.8798</param>
        <param name="max">2.8798</param>
      </command_interface>
      <command_interface name="velocity">
        <param name="min">-0.3</param>
        <param name="max">0.3</param>
      </command_interface>
      <state_interface name="position" />
      <state_interface name="velocity" />
      <state_interface name="effort" />
    </joint>
    <joint name="joint_5">
      <command_interface name="position">
        <param name="min">-3.927</param>
        <param name="max">1.8326</param>
      </command_interface>
      <command_interface name="velocity">
        <param name="min">-0.3</param>
        <param name="max">0.3</param>
      </command_interface>
      <state_interface name="position" />
      <state_interface name="velocity" />
      <state_interface name="effort" />
    </joint>
    <joint name="joint_6">
      <command_interface name="position">
        <param name="min">-3.2289</param>
        <param name="max">2.5307</param>
      </command_interface>
      <command_interface name="velocity">
        <param name="min">-0.3</param>
        <param name="max">0.3</param>
      </command_interface>
      <state_interface name="position" />
      <state_interface name="velocity" />
      <state_interface name="effort" />
    </joint>
    <joint name="joint_7">
      <command_interface name="position">
        <param name="min">-1.8326</param>
        <param name="max">3.927</param>
      </command_interface>
      <command_interface name="velocity">
        <param name="min">-0.3</param>
        <param name="max">0.3</param>
      </command_interface>
      <state_interface name="position" />
      <state_interface name="velocity" />
      <state_interface name="effort" />
    </joint>
    <joint name="gripper_joint">
      <command_interface name="position">
        <param name="min">0.0</param>
        <param name="max">1.0</param>
      </command_interface>
      <state_interface name="position" />
      <state_interface name="velocity" />
      <state_interface name="effort" />
    </joint>
    <sensor name="xlink_fts">
      <state_interface name="force.x" />
      <state_interface name="force.y" />
      <state_interface name="force.z" />
      <state_interface name="torque.x" />
      <state_interface name="torque.y" />
      <state_interface name="torque.z" />
    </sensor>
  </ros2_control>
</robot>